<mujoco>
  <body>
    <body name="torso" pos="0 0 0.14">
      <!-- ant 좌표 축 display -->
      <site name="ant0:torso" pos="0 0 0" rgba="0 0 0 0" size="0.02 0.02 0.02"></site>
      <site name="ant0_x_axes" pos="0.1 0 0" size="0.1 0.01 0.01" rgba="1 0 0 1" type="box"></site>
		  <site name="ant0_y_axes" pos="0 0.1 0" size="0.01 0.1 0.01" rgba="0 1 0 1" type="box"></site>
		  <site name="ant0_z_axes" pos="0 0 0.1" size="0.01 0.01 0.1" rgba="0 0 1 1" type="box"></site>
      
      <geom name="torso_geom" pos="0 0 0" size="0.09" type="sphere" class="robot0:grey"/>
      <body name="front_left_leg" pos="0 0 0">
        <geom fromto="0.0 0.0 0.0 0.05 0.05 0.0" name="aux_1_geom" size="0.02" type="capsule"/>
        <body name="aux_1" pos="0.05 0.05 0">
          <joint axis="0 0 1" name="hip_1" pos="0.0 0.0 0.0" range="-30 30" type="hinge"/>
          <geom fromto="0.0 0.0 0.0 0.05 0.05 0.0" name="left_leg_geom" size="0.02" type="capsule"/>
          <body pos="0.05 0.05 0">
            <joint axis="-1 1 0" name="ankle_1" pos="0.0 0.0 0.0" range="30 70" type="hinge"/>
            <geom fromto="0.0 0.0 0.0 0.1 0.1 0.0" name="left_ankle_geom" size="0.02" type="capsule"/>
          </body>
        </body>
      </body>
      <body name="front_right_leg" pos="0 0 0">
        <geom fromto="0.0 0.0 0.0 -0.05 0.05 0.0" name="aux_2_geom" size="0.02" type="capsule"/>
        <body name="aux_2" pos="-0.05 0.05 0">
          <joint axis="0 0 1" name="hip_2" pos="0.0 0.0 0.0" range="-30 30" type="hinge"/>
          <geom fromto="0.0 0.0 0.0 -0.05 0.05 0.0" name="right_leg_geom" size="0.02" type="capsule"/>
          <body pos="-0.05 0.05 0">
            <joint axis="1 1 0" name="ankle_2" pos="0.0 0.0 0.0" range="-70 -30" type="hinge"/>
            <geom fromto="0.0 0.0 0.0 -0.1 0.1 0.0" name="right_ankle_geom" size="0.02" type="capsule"/>
          </body>
        </body>
      </body>
      <body name="back_leg" pos="0 0 0">
        <geom fromto="0.0 0.0 0.0 -0.05 -0.05 0.0" name="aux_3_geom" size="0.02" type="capsule"/>
        <body name="aux_3" pos="-0.05 -0.05 0">
          <joint axis="0 0 1" name="hip_3" pos="0.0 0.0 0.0" range="-30 30" type="hinge"/>
          <geom fromto="0.0 0.0 0.0 -0.05 -0.05 0.0" name="back_leg_geom" size="0.02" type="capsule"/>
          <body pos="-0.05 -0.05 0">
            <joint axis="-1 1 0" name="ankle_3" pos="0.0 0.0 0.0" range="-70 -30" type="hinge"/>
            <geom fromto="0.0 0.0 0.0 -0.1 -0.1 0.0" name="third_ankle_geom" size="0.02" type="capsule"/>
          </body>
        </body>
      </body>
      <body name="right_back_leg" pos="0 0 0">
        <geom fromto="0.0 0.0 0.0 0.05 -0.05 0.0" name="aux_4_geom" size="0.02" type="capsule"/>
        <body name="aux_4" pos="0.05 -0.05 0">
          <joint axis="0 0 1" name="hip_4" pos="0.0 0.0 0.0" range="-30 30" type="hinge"/>
          <geom fromto="0.0 0.0 0.0 0.05 -0.05 0.0" name="rightback_leg_geom" size="0.02" type="capsule"/>
          <body pos="0.05 -0.05 0">
            <joint axis="1 1 0" name="ankle_4" pos="0.0 0.0 0.0" range="30 70" type="hinge"/>
            <geom fromto="0.0 0.0 0.0 0.1 -0.1 0.0" name="fourth_ankle_geom" size="0.02" type="capsule"/>
          </body>
        </body>
      </body>
    </body>
  </body>
</mujoco>
